INFO - 2023-03-13 19:11:21,739 - process: 11560 - scheduler.py - gerapy.server.core.scheduler - 105 - scheduler - successfully synced task with jobs with force
ERROR - 2023-03-13 19:11:31,109 - process: 11560 - utils.py - gerapy.server.core.utils - 564 - utils - HTTPConnectionPool(host='127.0.0.1', port=6800): Max retries exceeded with url: / (Caused by NewConnectionError('<urllib3.connection.HTTPConnection object at 0x0000025B1B7FAB60>: Failed to establish a new connection: [WinError 10061] 由于目标计算机积极拒绝，无法连接。'))
Traceback (most recent call last):
  File "D:\Program Files\python3\lib\site-packages\urllib3\connection.py", line 174, in _new_conn
    conn = connection.create_connection(
  File "D:\Program Files\python3\lib\site-packages\urllib3\util\connection.py", line 95, in create_connection
    raise err
  File "D:\Program Files\python3\lib\site-packages\urllib3\util\connection.py", line 85, in create_connection
    sock.connect(sa)
ConnectionRefusedError: [WinError 10061] 由于目标计算机积极拒绝，无法连接。

During handling of the above exception, another exception occurred:

Traceback (most recent call last):
  File "D:\Program Files\python3\lib\site-packages\urllib3\connectionpool.py", line 703, in urlopen
    httplib_response = self._make_request(
  File "D:\Program Files\python3\lib\site-packages\urllib3\connectionpool.py", line 398, in _make_request
    conn.request(method, url, **httplib_request_kw)
  File "D:\Program Files\python3\lib\site-packages\urllib3\connection.py", line 239, in request
    super(HTTPConnection, self).request(method, url, body=body, headers=headers)
  File "D:\Program Files\python3\lib\http\client.py", line 1282, in request
    self._send_request(method, url, body, headers, encode_chunked)
  File "D:\Program Files\python3\lib\http\client.py", line 1328, in _send_request
    self.endheaders(body, encode_chunked=encode_chunked)
  File "D:\Program Files\python3\lib\http\client.py", line 1277, in endheaders
    self._send_output(message_body, encode_chunked=encode_chunked)
  File "D:\Program Files\python3\lib\http\client.py", line 1037, in _send_output
    self.send(msg)
  File "D:\Program Files\python3\lib\http\client.py", line 975, in send
    self.connect()
  File "D:\Program Files\python3\lib\site-packages\urllib3\connection.py", line 205, in connect
    conn = self._new_conn()
  File "D:\Program Files\python3\lib\site-packages\urllib3\connection.py", line 186, in _new_conn
    raise NewConnectionError(
urllib3.exceptions.NewConnectionError: <urllib3.connection.HTTPConnection object at 0x0000025B1B7FAB60>: Failed to establish a new connection: [WinError 10061] 由于目标计算机积极拒绝，无法连接。

During handling of the above exception, another exception occurred:

Traceback (most recent call last):
  File "D:\Program Files\python3\lib\site-packages\requests\adapters.py", line 489, in send
    resp = conn.urlopen(
  File "D:\Program Files\python3\lib\site-packages\urllib3\connectionpool.py", line 787, in urlopen
    retries = retries.increment(
  File "D:\Program Files\python3\lib\site-packages\urllib3\util\retry.py", line 592, in increment
    raise MaxRetryError(_pool, url, error or ResponseError(cause))
urllib3.exceptions.MaxRetryError: HTTPConnectionPool(host='127.0.0.1', port=6800): Max retries exceeded with url: / (Caused by NewConnectionError('<urllib3.connection.HTTPConnection object at 0x0000025B1B7FAB60>: Failed to establish a new connection: [WinError 10061] 由于目标计算机积极拒绝，无法连接。'))

During handling of the above exception, another exception occurred:

Traceback (most recent call last):
  File "D:\Program Files\python3\lib\site-packages\gerapy\server\core\utils.py", line 562, in wrapper
    result = func(*args, **kwargs)
  File "D:\Program Files\python3\lib\site-packages\django\views\decorators\csrf.py", line 54, in wrapped_view
    return view_func(*args, **kwargs)
  File "D:\Program Files\python3\lib\site-packages\django\views\generic\base.py", line 71, in view
    return self.dispatch(request, *args, **kwargs)
  File "D:\Program Files\python3\lib\site-packages\rest_framework\views.py", line 509, in dispatch
    response = self.handle_exception(exc)
  File "D:\Program Files\python3\lib\site-packages\rest_framework\views.py", line 469, in handle_exception
    self.raise_uncaught_exception(exc)
  File "D:\Program Files\python3\lib\site-packages\rest_framework\views.py", line 480, in raise_uncaught_exception
    raise exc
  File "D:\Program Files\python3\lib\site-packages\rest_framework\views.py", line 506, in dispatch
    response = handler(request, *args, **kwargs)
  File "D:\Program Files\python3\lib\site-packages\rest_framework\decorators.py", line 50, in handler
    return func(*args, **kwargs)
  File "D:\Program Files\python3\lib\site-packages\gerapy\server\core\views.py", line 120, in client_status
    requests.get(scrapyd_url(client.ip, client.port), timeout=3)
  File "D:\Program Files\python3\lib\site-packages\requests\api.py", line 73, in get
    return request("get", url, params=params, **kwargs)
  File "D:\Program Files\python3\lib\site-packages\requests\api.py", line 59, in request
    return session.request(method=method, url=url, **kwargs)
  File "D:\Program Files\python3\lib\site-packages\requests\sessions.py", line 587, in request
    resp = self.send(prep, **send_kwargs)
  File "D:\Program Files\python3\lib\site-packages\requests\sessions.py", line 701, in send
    r = adapter.send(request, **kwargs)
  File "D:\Program Files\python3\lib\site-packages\requests\adapters.py", line 565, in send
    raise ConnectionError(e, request=request)
requests.exceptions.ConnectionError: HTTPConnectionPool(host='127.0.0.1', port=6800): Max retries exceeded with url: / (Caused by NewConnectionError('<urllib3.connection.HTTPConnection object at 0x0000025B1B7FAB60>: Failed to establish a new connection: [WinError 10061] 由于目标计算机积极拒绝，无法连接。'))
INFO - 2023-03-13 19:14:49,749 - process: 11560 - build.py - gerapy.server.core.build - 24 - build - successfully build project cve_spider to egg file C:\Users\loong\myspider\gerapy\projects\cve_spider\project-1.0-py3.10.egg
